hyperparameters_configured: model_arhitecture=gpt, block_size=128, batch_size=64, vocab_size=16000, n_layer=6, n_head=8, d_model=512, dropout=0.1, lr=0.006, weight_decay=0.0, evals_per_epoch=3, epochs=7, seed=1337, num_titles=100000, val_frac=0.1, log_file=./logs/mainrun.log
device_info: device=cpu
Traceback (most recent call last):
  File "/usr/local/lib/python3.10/dist-packages/huggingface_hub/utils/_http.py", line 409, in hf_raise_for_status
    response.raise_for_status()
  File "/usr/local/lib/python3.10/dist-packages/requests/models.py", line 1026, in raise_for_status
    raise HTTPError(http_error_msg, response=self)
requests.exceptions.HTTPError: 404 Client Error: Not Found for url: https://huggingface.co/datasets/julien040/hacker-news-posts/resolve/9e21b0f3c36bd7ce50b741ce966297a7f73cae38/hacker-news-posts.py

The above exception was the direct cause of the following exception:

Traceback (most recent call last):
  File "/usr/local/lib/python3.10/dist-packages/datasets/load.py", line 982, in dataset_module_factory
    api.hf_hub_download(
  File "/usr/local/lib/python3.10/dist-packages/huggingface_hub/utils/_validators.py", line 114, in _inner_fn
    return fn(*args, **kwargs)
  File "/usr/local/lib/python3.10/dist-packages/huggingface_hub/hf_api.py", line 5528, in hf_hub_download
    return hf_hub_download(
  File "/usr/local/lib/python3.10/dist-packages/huggingface_hub/utils/_validators.py", line 114, in _inner_fn
    return fn(*args, **kwargs)
  File "/usr/local/lib/python3.10/dist-packages/huggingface_hub/file_download.py", line 1010, in hf_hub_download
    return _hf_hub_download_to_cache_dir(
  File "/usr/local/lib/python3.10/dist-packages/huggingface_hub/file_download.py", line 1073, in _hf_hub_download_to_cache_dir
    (url_to_download, etag, commit_hash, expected_size, xet_file_data, head_call_error) = _get_metadata_or_catch_error(
  File "/usr/local/lib/python3.10/dist-packages/huggingface_hub/file_download.py", line 1546, in _get_metadata_or_catch_error
    metadata = get_hf_file_metadata(
  File "/usr/local/lib/python3.10/dist-packages/huggingface_hub/utils/_validators.py", line 114, in _inner_fn
    return fn(*args, **kwargs)
  File "/usr/local/lib/python3.10/dist-packages/huggingface_hub/file_download.py", line 1463, in get_hf_file_metadata
    r = _request_wrapper(
  File "/usr/local/lib/python3.10/dist-packages/huggingface_hub/file_download.py", line 286, in _request_wrapper
    response = _request_wrapper(
  File "/usr/local/lib/python3.10/dist-packages/huggingface_hub/file_download.py", line 310, in _request_wrapper
    hf_raise_for_status(response)
  File "/usr/local/lib/python3.10/dist-packages/huggingface_hub/utils/_http.py", line 420, in hf_raise_for_status
    raise _format(EntryNotFoundError, message, response) from e
huggingface_hub.errors.EntryNotFoundError: 404 Client Error. (Request ID: Root=1-68aedd9b-3f4733eb675471cf20ccaaef;ea41de9d-43ae-4cdd-8e16-adc44fbf9a54)

Entry Not Found for url: https://huggingface.co/datasets/julien040/hacker-news-posts/resolve/9e21b0f3c36bd7ce50b741ce966297a7f73cae38/hacker-news-posts.py.

During handling of the above exception, another exception occurred:

Traceback (most recent call last):
  File "/workspace/mainrun/train.py", line 256, in <module>
    main(cfg)
  File "/workspace/mainrun/train.py", line 129, in main
    train_titles, val_titles = get_titles(args.num_titles, args.seed, args.val_frac)
  File "/workspace/mainrun/train.py", line 68, in get_titles
    ds = load_dataset("julien040/hacker-news-posts", split="train", cache_dir="./data").shuffle(seed=seed)
  File "/usr/local/lib/python3.10/dist-packages/datasets/load.py", line 1392, in load_dataset
    builder_instance = load_dataset_builder(
  File "/usr/local/lib/python3.10/dist-packages/datasets/load.py", line 1132, in load_dataset_builder
    dataset_module = dataset_module_factory(
  File "/usr/local/lib/python3.10/dist-packages/datasets/load.py", line 1004, in dataset_module_factory
    ).get_module()
  File "/usr/local/lib/python3.10/dist-packages/datasets/load.py", line 591, in get_module
    standalone_yaml_path = cached_path(
  File "/usr/local/lib/python3.10/dist-packages/datasets/utils/file_utils.py", line 171, in cached_path
    output_path = huggingface_hub.HfApi(
  File "/usr/local/lib/python3.10/dist-packages/huggingface_hub/utils/_validators.py", line 114, in _inner_fn
    return fn(*args, **kwargs)
  File "/usr/local/lib/python3.10/dist-packages/huggingface_hub/hf_api.py", line 5528, in hf_hub_download
    return hf_hub_download(
  File "/usr/local/lib/python3.10/dist-packages/huggingface_hub/utils/_validators.py", line 114, in _inner_fn
    return fn(*args, **kwargs)
  File "/usr/local/lib/python3.10/dist-packages/huggingface_hub/file_download.py", line 1010, in hf_hub_download
    return _hf_hub_download_to_cache_dir(
  File "/usr/local/lib/python3.10/dist-packages/huggingface_hub/file_download.py", line 1073, in _hf_hub_download_to_cache_dir
    (url_to_download, etag, commit_hash, expected_size, xet_file_data, head_call_error) = _get_metadata_or_catch_error(
  File "/usr/local/lib/python3.10/dist-packages/huggingface_hub/file_download.py", line 1546, in _get_metadata_or_catch_error
    metadata = get_hf_file_metadata(
  File "/usr/local/lib/python3.10/dist-packages/huggingface_hub/utils/_validators.py", line 114, in _inner_fn
    return fn(*args, **kwargs)
  File "/usr/local/lib/python3.10/dist-packages/huggingface_hub/file_download.py", line 1463, in get_hf_file_metadata
    r = _request_wrapper(
  File "/usr/local/lib/python3.10/dist-packages/huggingface_hub/file_download.py", line 286, in _request_wrapper
    response = _request_wrapper(
  File "/usr/local/lib/python3.10/dist-packages/huggingface_hub/file_download.py", line 309, in _request_wrapper
    response = http_backoff(method=method, url=url, **params, retry_on_exceptions=(), retry_on_status_codes=(429,))
  File "/usr/local/lib/python3.10/dist-packages/huggingface_hub/utils/_http.py", line 310, in http_backoff
    response = session.request(method=method, url=url, **kwargs)
  File "/usr/local/lib/python3.10/dist-packages/requests/sessions.py", line 589, in request
    resp = self.send(prep, **send_kwargs)
  File "/usr/local/lib/python3.10/dist-packages/requests/sessions.py", line 703, in send
    r = adapter.send(request, **kwargs)
  File "/usr/local/lib/python3.10/dist-packages/huggingface_hub/utils/_http.py", line 96, in send
    return super().send(request, *args, **kwargs)
  File "/usr/local/lib/python3.10/dist-packages/requests/adapters.py", line 644, in send
    resp = conn.urlopen(
  File "/usr/local/lib/python3.10/dist-packages/urllib3/connectionpool.py", line 787, in urlopen
    response = self._make_request(
  File "/usr/local/lib/python3.10/dist-packages/urllib3/connectionpool.py", line 534, in _make_request
    response = conn.getresponse()
  File "/usr/local/lib/python3.10/dist-packages/urllib3/connection.py", line 565, in getresponse
    httplib_response = super().getresponse()
  File "/usr/lib/python3.10/http/client.py", line 1375, in getresponse
    response.begin()
  File "/usr/lib/python3.10/http/client.py", line 318, in begin
    version, status, reason = self._read_status()
  File "/usr/lib/python3.10/http/client.py", line 279, in _read_status
    line = str(self.fp.readline(_MAXLINE + 1), "iso-8859-1")
  File "/usr/lib/python3.10/socket.py", line 705, in readinto
    return self._sock.recv_into(b)
  File "/usr/lib/python3.10/ssl.py", line 1303, in recv_into
    return self.read(nbytes, buffer)
  File "/usr/lib/python3.10/ssl.py", line 1159, in read
    return self._sslobj.read(len, buffer)
KeyboardInterrupt
Exception ignored in atexit callback: <function _start_and_connect_service.<locals>.teardown_atexit at 0xff71e28b5240>
Traceback (most recent call last):
  File "/usr/local/lib/python3.10/dist-packages/wandb/sdk/lib/service/service_connection.py", line 54, in teardown_atexit
    conn.teardown(hooks.exit_code)
  File "/usr/local/lib/python3.10/dist-packages/wandb/sdk/lib/service/service_connection.py", line 182, in teardown
    self._router.join()
  File "/usr/local/lib/python3.10/dist-packages/wandb/sdk/interface/router.py", line 75, in join
    self._thread.join()
  File "/usr/lib/python3.10/threading.py", line 1096, in join
    self._wait_for_tstate_lock()
  File "/usr/lib/python3.10/threading.py", line 1116, in _wait_for_tstate_lock
    if lock.acquire(block, timeout):
KeyboardInterrupt:
